Workbook

Sheet Результаты опроса
A1: ID | B1: Время создания | C1: Пожалуйста, укажите ваш возраст: | D1: Сталкивались ли вы (или ваши близкие) за последний год с одной из этих проблем? (Множественный выбор) / Кровоточивость десен при чистке. | E1: Сталкивались ли вы (или ваши близкие) за последний год с одной из этих проблем? (Множественный выбор) / Резкая боль от холодного/горячего/сладкого (чувствительность). | F1: Сталкивались ли вы (или ваши близкие) за последний год с одной из этих проблем? (Множественный выбор) / Воспаление или рыхлость десен. | G1: Сталкивались ли вы (или ваши близкие) за последний год с одной из этих проблем? (Множественный выбор) / Ни с чем из перечисленного (У меня идеальные зубы). | H1: Как вы обычно решаете такие проблемы? | I1: Представьте, что у вас сильно разболелась десна или зуб. Чьей рекомендации при выборе средства вы доверитесь на 100%? | J1: Представьте зубную пасту, в комплекте с которой идут таблетки-индикаторы (окрашивают налет, показывая, где вы плохо почистили). Насколько это было бы вам полезно? / Пожалуйста, оцените по шкале от 1 до . | K1: Где, по вашему мнению, должен продаваться такой профессиональный продукт? | L1: При какой цене вы побоитесь покупать эту пасту, решив, что это подделка? (Укажите число в рублях) | M1: Какая цена кажется вам отличной сделкой (выгодной покупкой за такие инновации)? | N1: При какой цене паста покажется вам дорогой, но вы все равно купите её ради гарантированного лечебного эффекта? (Укажите число в рублях) | O1: При какой цене вы точно откажетесь от покупки? (Укажите число в рублях) | P1: Представьте, что вы пришли в аптеку за лечебной пастой. На полке стоят два лидера: Lacalut Aktiv (400 руб.) — базовая лечебная паста. Oral-B Pro-Clinic Total Restore (490 руб.) — паста с премиальным составом, в комплекте с которой идут таблетки-индикаторы налета. Какой вариант вы купите? | Q1: Если у вас лично нет проблем с деснами, купили бы вы такой набор (Паста + Индикаторы) в подарок родителям или бабушке/дедушке, зная, что это избавит их от боли?
A2: 2323734998 | B2: 2026-03-02 18:33:09 | C2: 18 – 25 лет | G2: Ни с чем из перечисленного (У меня идеальные зубы). | H2: Иду к стоматологу. | I2: Совету моего стоматолога. | J2: 8 | K2: Только в аптеках и клиниках. | L2: 200 | M2: 400 | N2: 600 | O2: 1000 | P2: Выберу Oral-B (доплачу за инновацию и контроль) | Q2: Да, определенно.
A3: 2323738819 | B3: 2026-03-02 18:36:16 | C3: 26 – 35 лет | E3: Резкая боль от холодного/горячего/сладкого (чувствительность). | H3: Иду к стоматологу. | I3: Совету моего стоматолога. | J3: 9 | K3: Только в аптеках и клиниках. | L3: 100 | M3: 500 | N3: 700 | O3: 1000 | P3: Куплю то, что прямо скажет мой врач (даже если это 500 руб) | Q3: Да, определенно.
A4: 2323779913 | B4: 2026-03-02 19:11:28 | C4: 36 – 45 лет | E4: Резкая боль от холодного/горячего/сладкого (чувствительность). | H4: Покупаю любую пасту с надписью "Травы / Защита" в супермаркете. | I4: Рекомендации фармацевта в аптеке. | J4: 7 | K4: В любом супермаркете рядом с чипсами. | L4: 150 | M4: 450 | N4: 750 | O4: 1200 | P4: Выберу Oral-B (доплачу за инновацию и контроль) | Q4: Да, определенно.
A5: 2323903562 | B5: 2026-03-02 20:59:10 | C5: 26 – 35 лет | E5: Резкая боль от холодного/горячего/сладкого (чувствительность). | H5: Иду к стоматологу. | I5: Совету моего стоматолога. | J5: 5 | K5: Только в аптеках и клиниках. | L5: 100 | M5: 200 | N5: 300 | O5: 400 | P5: Куплю то, что прямо скажет мой врач (даже если это 500 руб) | Q5: Возможно.
A6: 2323904813 | B6: 2026-03-02 21:00:19 | C6: 26 – 35 лет | E6: Резкая боль от холодного/горячего/сладкого (чувствительность). | H6: Иду к стоматологу. | I6: Совету моего стоматолога. | J6: 8 | K6: Только в аптеках и клиниках. | L6: 200 | M6: 450 | N6: 600 | O6: 1000 | P6: Куплю то, что прямо скажет мой врач (даже если это 500 руб) | Q6: Возможно.
A7: 2323908103 | B7: 2026-03-02 21:03:20 | C7: 36 – 45 лет | G7: Ни с чем из перечисленного (У меня идеальные зубы). | H7: Иду к стоматологу. | I7: Совету моего стоматолога. | J7: 10 | K7: Только в аптеках и клиниках. | L7: 50 | M7: 100 | N7: 200 | O7: 300 | P7: Выберу Lacalut (мне достаточно базового лечения). | Q7: Возможно.
A8: 2323942651 | B8: 2026-03-02 21:36:44 | C8: 36 – 45 лет | E8: Резкая боль от холодного/горячего/сладкого (чувствительность). | H8: Покупаю лечебную пасту в аптеке (Lacalut, Sensodyne, Parodontax). | I8: Совету моего стоматолога. | J8: 4 | K8: Только в аптеках и клиниках. | L8: 200 | M8: 350 | N8: 450 | O8: 500 | P8: Выберу Lacalut (мне достаточно базового лечения). | Q8: Возможно.
A9: 2323947623 | B9: 2026-03-02 21:41:48 | C9: 46+ лет | D9: Кровоточивость десен при чистке. | H9: Ничего не делаю, жду, пока само пройдет. | I9: Совету моего стоматолога. | J9: 4 | K9: Только в аптеках и клиниках. | L9: 200 | M9: 350 | N9: 400 | O9: 410 | P9: Куплю то, что прямо скажет мой врач (даже если это 500 руб) | Q9: Нет.
A10: 2324199355 | B10: 2026-03-03 07:41:17 | C10: 36 – 45 лет | E10: Резкая боль от холодного/горячего/сладкого (чувствительность). | H10: Покупаю любую пасту с надписью "Травы / Защита" в супермаркете. | I10: Рекомендации фармацевта в аптеке. | J10: 8 | K10: Только в аптеках и клиниках. | L10: 100 | M10: 350 | N10: 500 | O10: 750 | P10: Выберу Oral-B (доплачу за инновацию и контроль) | Q10: Возможно.
A11: 2324797300 | B11: 2026-03-03 14:42:35 | C11: 36 – 45 лет | G11: Ни с чем из перечисленного (У меня идеальные зубы). | H11: Покупаю лечебную пасту в аптеке (Lacalut, Sensodyne, Parodontax). | I11: Совету моего стоматолога. | J11: 7 | K11: Только в аптеках и клиниках. | L11: 500 | M11: 1000 | N11: 2000 | O11: 2100 | P11: Куплю то, что прямо скажет мой врач (даже если это 500 руб) | Q11: Возможно.
A12: 2325335258 | B12: 2026-03-03 21:47:05 | C12: 46+ лет | D12: Кровоточивость десен при чистке. | F12: Воспаление или рыхлость десен. | H12: Иду к стоматологу. | I12: Совету моего стоматолога. | J12: 7 | K12: Только в аптеках и клиниках. | L12: 100 | M12: 380 | N12: 500 | O12: 700 | P12: Куплю то, что прямо скажет мой врач (даже если это 500 руб) | Q12: Да, определенно.
A13: 2325341543 | B13: 2026-03-03 21:53:40 | C13: 36 – 45 лет | F13: Воспаление или рыхлость десен. | H13: Ничего не делаю, жду, пока само пройдет. | I13: Совету моего стоматолога. | J13: 10 | K13: Только в аптеках и клиниках. | L13: 250 | M13: 350 | N13: 500 | O13: 1000 | P13: Куплю то, что прямо скажет мой врач (даже если это 500 руб) | Q13: Да, определенно.
A14: 2325342826 | B14: 2026-03-03 21:55:04 | C14: 18 – 25 лет | D14: Кровоточивость десен при чистке. | H14: Иду к стоматологу. | I14: Совету моего стоматолога. | J14: 10 | K14: Только в аптеках и клиниках. | L14: 199 | M14: 699 | N14: 999 | O14: 1599 | P14: Выберу Oral-B (доплачу за инновацию и контроль) | Q14: Возможно.
A15: 2325349874 | B15: 2026-03-03 22:02:53 | C15: 36 – 45 лет | D15: Кровоточивость десен при чистке. | E15: Резкая боль от холодного/горячего/сладкого (чувствительность). | H15: Покупаю лечебную пасту в аптеке (Lacalut, Sensodyne, Parodontax). | I15: Совету моего стоматолога. | J15: 10 | K15: Только в аптеках и клиниках. | L15: 150 | M15: 400 | N15: 600 | O15: 1000 | P15: Куплю то, что прямо скажет мой врач (даже если это 500 руб) | Q15: Да, определенно.
A16: 2325357976 | B16: 2026-03-03 22:12:37 | C16: 36 – 45 лет | D16: Кровоточивость десен при чистке. | E16: Резкая боль от холодного/горячего/сладкого (чувствительность). | H16: Ничего не делаю, жду, пока само пройдет. | I16: Совету моего стоматолога. | J16: 5 | K16: Только в аптеках и клиниках. | L16: 100 | M16: 1000 | N16: 3000 | O16: 5000 | P16: Куплю то, что прямо скажет мой врач (даже если это 500 руб) | Q16: Да, определенно.
A17: 2325360318 | B17: 2026-03-03 22:15:32 | C17: 46+ лет | D17: Кровоточивость десен при чистке. | F17: Воспаление или рыхлость десен. | H17: Иду к стоматологу. | I17: Отзывам на маркетплейсах. | J17: 8 | K17: В любом супермаркете рядом с чипсами. | L17: 100 | M17: 500 | N17: 800 | O17: 1000 | P17: Куплю то, что прямо скажет мой врач (даже если это 500 руб) | Q17: Да, определенно.
A18: 2325361352 | B18: 2026-03-03 22:16:54 | C18: 36 – 45 лет | G18: Ни с чем из перечисленного (У меня идеальные зубы). | H18: Иду к стоматологу. | I18: Совету моего стоматолога. | J18: 1 | K18: Только в аптеках и клиниках. | L18: 100 | M18: 250 | N18: 300 | O18: 500 | P18: Куплю то, что прямо скажет мой врач (даже если это 500 руб) | Q18: Возможно.
A19: 2325366490 | B19: 2026-03-03 22:23:15 | C19: 36 – 45 лет | D19: Кровоточивость десен при чистке. | E19: Резкая боль от холодного/горячего/сладкого (чувствительность). | H19: Ничего не делаю, жду, пока само пройдет. | I19: Совету моего стоматолога. | J19: 7 | K19: Только в аптеках и клиниках. | L19: 200 | M19: 350 | N19: 500 | O19: 600 | P19: Куплю то, что прямо скажет мой врач (даже если это 500 руб) | Q19: Возможно.
A20: 2325366559 | B20: 2026-03-03 22:23:21 | C20: 36 – 45 лет | E20: Резкая боль от холодного/горячего/сладкого (чувствительность). | H20: Ничего не делаю, жду, пока само пройдет. | I20: Отзывам на маркетплейсах. | J20: 10 | K20: В любом супермаркете рядом с чипсами. | L20: 500 | M20: 0 | N20: 2000 | O20: 5000 | P20: Выберу Oral-B (доплачу за инновацию и контроль) | Q20: Да, определенно.
A21: 2325368218 | B21: 2026-03-03 22:25:32 | C21: 36 – 45 лет | D21: Кровоточивость десен при чистке. | H21: Ничего не делаю, жду, пока само пройдет. | I21: Совету моего стоматолога. | J21: 10 | K21: В любом супермаркете рядом с чипсами. | L21: 300 | M21: 500 | N21: 1000 | O21: 2000 | P21: Куплю то, что прямо скажет мой врач (даже если это 500 руб) | Q21: Да, определенно.
A22: 2325369239 | B22: 2026-03-03 22:26:54 | C22: 36 – 45 лет | E22: Резкая боль от холодного/горячего/сладкого (чувствительность). | H22: Ничего не делаю, жду, пока само пройдет. | I22: Совету моего стоматолога. | J22: 8 | K22: В любом супермаркете рядом с чипсами. | L22: 100 | M22: 120 | N22: 200 | O22: 250 | P22: Выберу Oral-B (доплачу за инновацию и контроль) | Q22: Возможно.
A23: 2325369830 | B23: 2026-03-03 22:27:40 | C23: 36 – 45 лет | E23: Резкая боль от холодного/горячего/сладкого (чувствительность). | H23: Ничего не делаю, жду, пока само пройдет. | I23: Совету моего стоматолога. | J23: 8 | K23: В любом супермаркете рядом с чипсами. | L23: 200 | M23: 500 | N23: 600 | O23: 700 | P23: Выберу Oral-B (доплачу за инновацию и контроль) | Q23: Возможно.
A24: 2325377840 | B24: 2026-03-03 22:37:19 | C24: 46+ лет | E24: Резкая боль от холодного/горячего/сладкого (чувствительность). | H24: Покупаю лечебную пасту в аптеке (Lacalut, Sensodyne, Parodontax). | I24: Совету моего стоматолога. | J24: 8 | K24: В любом супермаркете рядом с чипсами. | L24: 300 | M24: 800 | N24: 1200 | O24: 2000 | P24: Выберу Oral-B (доплачу за инновацию и контроль) | Q24: Да, определенно.
A25: 2325380262 | B25: 2026-03-03 22:40:31 | C25: 36 – 45 лет | E25: Резкая боль от холодного/горячего/сладкого (чувствительность). | H25: Покупаю лечебную пасту в аптеке (Lacalut, Sensodyne, Parodontax). | I25: Совету моего стоматолога. | J25: 10 | K25: В любом супермаркете рядом с чипсами. | L25: 200 | M25: 500 | N25: 800 | O25: 1000 | P25: Выберу Oral-B (доплачу за инновацию и контроль) | Q25: Да, определенно.
A26: 2325382787 | B26: 2026-03-03 22:43:54 | C26: 36 – 45 лет | G26: Ни с чем из перечисленного (У меня идеальные зубы). | H26: Иду к стоматологу. | I26: Совету моего стоматолога. | J26: 10 | K26: Только в аптеках и клиниках. | L26: 200 | M26: 458 | N26: 600 | O26: 1000 | P26: Выберу Oral-B (доплачу за инновацию и контроль) | Q26: Да, определенно.
A27: 2325383682 | B27: 2026-03-03 22:45:09 | C27: 36 – 45 лет | G27: Ни с чем из перечисленного (У меня идеальные зубы). | H27: Ничего не делаю, жду, пока само пройдет. | I27: Совету моего стоматолога. | J27: 1 | K27: Только в аптеках и клиниках. | L27: 200 | M27: 400 | N27: 700 | O27: 1000 | P27: Куплю то, что прямо скажет мой врач (даже если это 500 руб) | Q27: Возможно.
A28: 2325385647 | B28: 2026-03-03 22:47:52 | C28: 36 – 45 лет | D28: Кровоточивость десен при чистке. | E28: Резкая боль от холодного/горячего/сладкого (чувствительность). | H28: Покупаю любую пасту с надписью "Травы / Защита" в супермаркете. | I28: Совету моего стоматолога. | J28: 10 | K28: В любом супермаркете рядом с чипсами. | L28: 200 | M28: 400 | N28: 1500 | O28: 2000 | P28: Выберу Oral-B (доплачу за инновацию и контроль) | Q28: Возможно.
A29: 2325389021 | B29: 2026-03-03 22:52:38 | C29: 36 – 45 лет | E29: Резкая боль от холодного/горячего/сладкого (чувствительность). | H29: Ничего не делаю, жду, пока само пройдет. | I29: Совету моего стоматолога. | J29: 10 | K29: В любом супермаркете рядом с чипсами. | L29: 200 | M29: 500 | N29: 1000 | O29: 5000 | P29: Выберу Oral-B (доплачу за инновацию и контроль) | Q29: Да, определенно.
A30: 2325389153 | B30: 2026-03-03 22:52:49 | C30: 46+ лет | D30: Кровоточивость десен при чистке. | E30: Резкая боль от холодного/горячего/сладкого (чувствительность). | H30: Ничего не делаю, жду, пока само пройдет. | I30: Совету моего стоматолога. | J30: 10 | K30: В любом супермаркете рядом с чипсами. | L30: 500 | M30: 1200 | N30: 1500 | O30: 3000 | P30: Выберу Oral-B (доплачу за инновацию и контроль) | Q30: Да, определенно.
A31: 2325391207 | B31: 2026-03-03 22:55:47 | C31: 36 – 45 лет | G31: Ни с чем из перечисленного (У меня идеальные зубы). | H31: Иду к стоматологу. | I31: Совету моего стоматолога. | J31: 6 | K31: Только в аптеках и клиниках. | L31: 52 | M31: 150 | N31: 230 | O31: 300 | P31: Выберу Lacalut (мне достаточно базового лечения). | Q31: Да, определенно.
A32: 2325392535 | B32: 2026-03-03 22:57:50 | C32: 36 – 45 лет | G32: Ни с чем из перечисленного (У меня идеальные зубы). | H32: Иду к стоматологу. | I32: Совету моего стоматолога. | J32: 10 | K32: Только в аптеках и клиниках. | L32: 200 | M32: 500 | N32: 800 | O32: 1500 | P32: Выберу Oral-B (доплачу за инновацию и контроль) | Q32: Да, определенно.
A33: 2325393066 | B33: 2026-03-03 22:58:34 | C33: 18 – 25 лет | E33: Резкая боль от холодного/горячего/сладкого (чувствительность). | H33: Иду к стоматологу. | I33: Совету моего стоматолога. | J33: 4 | K33: В любом супермаркете рядом с чипсами. | L33: 500 | M33: 350 | N33: 1500 | O33: 3000 | P33: Выберу Lacalut (мне достаточно базового лечения). | Q33: Да, определенно.
A34: 2325406335 | B34: 2026-03-03 23:19:43 | C34: 36 – 45 лет | D34: Кровоточивость десен при чистке. | E34: Резкая боль от холодного/горячего/сладкого (чувствительность). | F34: Воспаление или рыхлость десен. | H34: Покупаю лечебную пасту в аптеке (Lacalut, Sensodyne, Parodontax). | I34: Совету моего стоматолога. | J34: 7 | K34: В любом супермаркете рядом с чипсами. | L34: 200 | M34: 500 | N34: 800 | O34: 1000 | P34: Выберу Oral-B (доплачу за инновацию и контроль) | Q34: Да, определенно.
A35: 2325410442 | B35: 2026-03-03 23:26:51 | C35: 46+ лет | D35: Кровоточивость десен при чистке. | E35: Резкая боль от холодного/горячего/сладкого (чувствительность). | H35: Иду к стоматологу. | I35: Совету моего стоматолога. | J35: 8 | K35: Только в аптеках и клиниках. | L35: 100 | M35: 200 | N35: 350 | O35: 500 | P35: Куплю то, что прямо скажет мой врач (даже если это 500 руб) | Q35: Да, определенно.
A36: 2325418499 | B36: 2026-03-03 23:42:16 | C36: 26 – 35 лет | D36: Кровоточивость десен при чистке. | H36: Покупаю лечебную пасту в аптеке (Lacalut, Sensodyne, Parodontax). | I36: Совету моего стоматолога. | J36: 6 | K36: Только в аптеках и клиниках. | L36: 350 | M36: 300 | N36: 1000 | O36: 1200 | P36: Выберу Oral-B (доплачу за инновацию и контроль) | Q36: Да, определенно.
A37: 2325427724 | B37: 2026-03-04 00:02:31 | C37: 18 – 25 лет | E37: Резкая боль от холодного/горячего/сладкого (чувствительность). | H37: Ничего не делаю, жду, пока само пройдет. | I37: Совету моего стоматолога. | J37: 2 | K37: В любом супермаркете рядом с чипсами. | L37: 150 | M37: 400 | N37: 650 | O37: 1500 | P37: Выберу Lacalut (мне достаточно базового лечения). | Q37: Возможно.
A38: 2325430593 | B38: 2026-03-04 00:09:18 | C38: 36 – 45 лет | E38: Резкая боль от холодного/горячего/сладкого (чувствительность). | F38: Воспаление или рыхлость десен. | H38: Ничего не делаю, жду, пока само пройдет. | I38: Рекламе по ТВ / в Интернете. | J38: 2 | K38: В любом супермаркете рядом с чипсами. | L38: 5 | M38: 5 | N38: 5 | O38: 5 | P38: Куплю то, что прямо скажет мой врач (даже если это 500 руб) | Q38: Возможно.
A39: 2325434676 | B39: 2026-03-04 00:21:04 | C39: 18 – 25 лет | G39: Ни с чем из перечисленного (У меня идеальные зубы). | H39: Ничего не делаю, жду, пока само пройдет. | I39: Отзывам на маркетплейсах. | J39: 7 | K39: В любом супермаркете рядом с чипсами. | L39: 200 | M39: 200 | N39: 300 | O39: 1000 | P39: Куплю то, что прямо скажет мой врач (даже если это 500 руб) | Q39: Возможно.
A40: 2325435713 | B40: 2026-03-04 00:23:53 | C40: 18 – 25 лет | G40: Ни с чем из перечисленного (У меня идеальные зубы). | H40: Ничего не делаю, жду, пока само пройдет. | I40: Отзывам на маркетплейсах. | J40: 7 | K40: В любом супермаркете рядом с чипсами. | L40: 200 | M40: 200 | N40: 300 | O40: 1000 | P40: Куплю то, что прямо скажет мой врач (даже если это 500 руб) | Q40: Возможно.
...

Sheet Анализ общей выборки (N=88)
A1: N=88
A2: Охват проблемы (проблемы полости рта) | B2: =1 - (COUNTIF('Результаты опроса'!G:G, "*Ни с чем*") -1)/88 -> 0.54545455 | C2: Каждый второй респондент сталкивается с проблемами ротовой полости.среди них 24% - кровоточивость | G2: Возраст | H2: Опрошено(человек) | I2: Есть проблемы | J2: %
A3: Оценили инновацию с таблетками-индикаторами на 6+ | B3: =COUNTIF('Результаты опроса'!J:J,">=6")/88 -> 0.875 | G3: 18-25 лет | H3: =COUNTIF('Результаты опроса'!C:C, "18 – 25 лет") -> 32 | I3: =H3 - COUNTIFS('Результаты опроса'!C:C, "18 – 25 лет", 'Результаты опроса'!G:G, "*Ни с чем*") -> 5 | J3: =I3/H3 -> 0.15625
A4: Средняя оценка инновации с таблетками-индикаторами | B4: =AVERAGE('Результаты опроса'!J:J) -> 7.5 | G4: 26 – 35 лет | H4: =COUNTIF('Результаты опроса'!C:C, "26 – 35 лет") -> 9 | I4: =H4 - COUNTIFS('Результаты опроса'!C:C, "26 – 35 лет", 'Результаты опроса'!G:G, "*Ни с чем*") -> 7 | J4: =I4/H4 -> 0.77777778
A5: Oral-b VS Lacalut(490руб против 400руб) - Oral-b | B5: =(COUNTIF('Результаты опроса'!P:P,"*Oral-B*")-1)/88 -> 0.34090909 | C5: почти в 5 раз больше людей выберут Oral-B против Lacalut до подключения медпредов | G5: 36 – 45 лет | H5: =COUNTIF('Результаты опроса'!C:C, "36 – 45 лет") -> 34 | I5: =H5 - COUNTIFS('Результаты опроса'!C:C, "36 – 45 лет", 'Результаты опроса'!G:G, "*Ни с чем*") -> 25 | J5: =I5/H5 -> 0.73529412
A6: Oral-b VS Lacalut(490руб против 400руб) - Lacalut | B6: =(COUNTIF('Результаты опроса'!P:P,"*Lacalut*")-1)/88 -> 0.068181818 | G6: 46+ лет | H6: =COUNTIF('Результаты опроса'!C:C, "46+ лет") -> 13 | I6: =H6 - COUNTIFS('Результаты опроса'!C:C, "46+ лет", 'Результаты опроса'!G:G, "*Ни с чем*") -> 11 | J6: =I6/H6 -> 0.84615385
A7: Выбор зависит от рекомендации врача | B7: =COUNTIF('Результаты опроса'!P:P,"*Врач*")/88 -> 0.59090909 | C7: при подключении медпредов ~93% выберут Oral-B | G7: Итого(26+ лет) | H7: =SUM(H4:H6) -> 56 | I7: =SUM(I4:I6) -> 43 | J7: =I7/H7 -> 0.76785714
A11: кровоточивость | B11: =(COUNTIF('Результаты опроса'!D:D, "*Кровоточивость*") -1)/88 -> 0.23863636
A12: гиперчувствительность | B12: =(COUNTIF('Результаты опроса'!E:E, "*Резкая*") -1)/88 -> 0.44318182 | C12: - основной конкурент Sensodyne
A13: воспаления | B13: =(COUNTIF('Результаты опроса'!F:F, "*Рыхлость*") -1)/88 -> 0.079545455
A14: Отсутствие проблем | B14: =1-B11-B12-B13 -> 0.23863636
A26: Индекс доверия(Channel Trust)
A27: Совет стоматолога | B27: =COUNTIF('Результаты опроса'!I:I,"*Совету моего*")/88 -> 0.625
A28: Отзывы на маркетплейсах(E-com) | B28: =COUNTIF('Результаты опроса'!I:I,"*Отзывам*")/88 -> 0.31818182
A29: Фармацевты + ТВ | B29: =1-B27-B28 -> 0.056818182
A31: Основной ресурс влияния — врачебное сообщество и социальное доказательство (E-com отзывы), а не классическая ТВ реклама
A42: Метод Ван-Вестендорпа анализа цены | R42: График в PNG:
A65: PMC (Нижний предел) | B65: Слишком дешево + Дорого | C65: =300 + (350-300) * ( ('PSM Общая выборка'!B6 - 'PSM Общая выборка'!D6) / ( ('PSM Общая выборка'!B6 - 'PSM Общая выборка'!D6) - ('PSM Общая выборка'!B8 - 'PSM Общая выборка'!D8) ) ) -> 331.03448 | D65: Ниже этой цены пасту покупать не будут, так как не поверят в её лечебный эффект.
A66: PME (Верхний предел) | B66: Слишком дорого + Выгодно | C66: =700 + (750-700) * ( ('PSM Общая выборка'!C17 - 'PSM Общая выборка'!E17) / ( ('PSM Общая выборка'!C17 - 'PSM Общая выборка'!E17) - ('PSM Общая выборка'!C19 - 'PSM Общая выборка'!E19) ) ) -> 740 | D66: Выше этой цены паста становится слишком дорогой даже для лояльных клиентов.
A67: OPP (Оптимальная цена) | B67: Слишком дешево + Слишком дорого | C67: =450 + (500-450) * ( ('PSM Общая выборка'!B11 - 'PSM Общая выборка'!E11) / ( ('PSM Общая выборка'!B11 - 'PSM Общая выборка'!E11) - ('PSM Общая выборка'!B13 - 'PSM Общая выборка'!E13) ) ) -> 482.5 | D67: Здесь страх переплаты равен страху подделки. Идеально для входа на рынок. | E67: Хотя оптимальная цена (OPP) по опросу составляет около 483 рублей, мы выбрали стратегическую цену 490 рублей. Это позволяет нам оставаться в зоне комфорта потребителя, при этом позиционируясь выше точки безразличия (IPP = 443 руб.), что подчеркивает инновационность продукта с индикаторными таблетками
A68: IPP (Безразличная цена) | B68: Выгодно + Дорого | C68: =400 + (450-400) * ( ('PSM Общая выборка'!C9 - 'PSM Общая выборка'!D9) / ( ('PSM Общая выборка'!C9 - 'PSM Общая выборка'!D9) - ('PSM Общая выборка'!C11 - 'PSM Общая выборка'!D11) ) ) -> 442.85714 | D68: Это цена, которую рынок считает «обычной». Мы намеренно ставим 490 ₽, чтобы быть чуть выше «среднего».

Sheet Стратегические выводы
A1: Сегмент | B1: Значение | C1: Вывод для стратегии
A2: Ядро аудитории | B2: 30+(Оценка 8.1/10) | C2: Таргетинг в Digital только на 30+, исключаем студентов.
A3: Потенциал подарков | B3: 99% респондентов готовы купить пасту в подарок родителям | C3: Запуск "Семейного набора" (Family Pack) для заботы о родителях.
A4: Барьер "Ждунов" | B4: 64% молодежи игнорируют проблемы ротовой полости | C4: Игнорируем этот сегмент на старте. Высокий CAC, низкий LTV.
A9: Таблетки-индикаторы
A10: Оценка инновации (18-25 лет) | B10: =AVERAGEIF('Результаты опроса'!C:C, "18 – 25 лет", 'Результаты опроса'!J:J) -> 7 | C10: Молодежь еще не чувствует ценности продукта
A11: Оценка инновации (26-35 лет) | B11: =AVERAGEIF('Результаты опроса'!C:C, "26 – 35 лет", 'Результаты опроса'!J:J) -> 8.1111111 | C11: Аудитория 26+ (8.1 балла) — наше золотое ядро. Они уже столкнулись с проблемами
A12: Оценка инновации (46+ лет) | B12: =AVERAGEIF('Результаты опроса'!C:C, "46+ лет", 'Результаты опроса'!J:J) -> 8.1538462 | C12: Старшее поколение максимально заинтересовано в спасении зубов
A15: Потенциал подарков
A16: Готовы купить в подарок | B16: =(COUNTIF('Результаты опроса'!Q:Q, "*Да, определенно*") + COUNTIF('Результаты опроса'!Q:Q, "*Возможно*")) / 88 -> 0.98863636 | C16: 99% аудитории готовы купить набор в подарок. Это обосновывает запуск Family Pack к праздникам
A17: Точно купят (Hard core) | B17: =COUNTIF('Результаты опроса'!Q:Q, "*Да, определенно*") / 88 -> 0.42045455 | C17: 42% гарантированных продаж через канал подарков
A21: Ждуны
A22: % Молодежи среди «Ждунов» | B22: =COUNTIFS('Результаты опроса'!H:H, "*Ничего не делаю*", 'Результаты опроса'!C:C, "18 – 25 лет") / COUNTIF('Результаты опроса'!H:H, "*Ничего не делаю*") -> 0.64285714 | C22: «64% тех, кто игнорирует проблемы — это студенты. Мы исключаем их из таргетинга, чтобы снизить стоимость привлечения клиента (CAC)».

Sheet PSM  Общая выборка
A1: Шкала цен | B1: L: Слишком дешево | C1: M: Выгодно | D1: N: Дорого | E1: O: Слишком дорого
A2: 100 | B2: =1 - COUNTIF('Результаты опроса'!L:L, "<=" & A2)/88 -> 0.73863636 | C2: =1 - COUNTIF('Результаты опроса'!M:M, "<=" & A2)/88 -> 0.96590909 | D2: =1 - COUNTIF('Результаты опроса'!N:N, ">=" & A2)/88 -> 0.011363636 | E2: =1 - COUNTIF('Результаты опроса'!O:O, ">=" & A2)/88 -> 0.011363636
A3: =A2+50 -> 150 | B3: =1 - COUNTIF('Результаты опроса'!L:L, "<=" & A3)/88 -> 0.65909091 | C3: =1 - COUNTIF('Результаты опроса'!M:M, "<=" & A3)/88 -> 0.94318182 | D3: =1 - COUNTIF('Результаты опроса'!N:N, ">=" & A3)/88 -> 0.011363636 | E3: =1 - COUNTIF('Результаты опроса'!O:O, ">=" & A3)/88 -> 0.011363636
A4: =A3+50 -> 200 | B4: =1 - COUNTIF('Результаты опроса'!L:L, "<=" & A4)/88 -> 0.31818182 | C4: =1 - COUNTIF('Результаты опроса'!M:M, "<=" & A4)/88 -> 0.79545455 | D4: =1 - COUNTIF('Результаты опроса'!N:N, ">=" & A4)/88 -> 0.011363636 | E4: =1 - COUNTIF('Результаты опроса'!O:O, ">=" & A4)/88 -> 0.011363636
A5: =A4+50 -> 250 | B5: =1 - COUNTIF('Результаты опроса'!L:L, "<=" & A5)/88 -> 0.29545455 | C5: =1 - COUNTIF('Результаты опроса'!M:M, "<=" & A5)/88 -> 0.76136364 | D5: =1 - COUNTIF('Результаты опроса'!N:N, ">=" & A5)/88 -> 0.045454545 | E5: =1 - COUNTIF('Результаты опроса'!O:O, ">=" & A5)/88 -> 0.011363636
A6: =A5+50 -> 300 | B6: =1 - COUNTIF('Результаты опроса'!L:L, "<=" & A6)/88 -> 0.25 | C6: =1 - COUNTIF('Результаты опроса'!M:M, "<=" & A6)/88 -> 0.70454545 | D6: =1 - COUNTIF('Результаты опроса'!N:N, ">=" & A6)/88 -> 0.045454545 | E6: =1 - COUNTIF('Результаты опроса'!O:O, ">=" & A6)/88 -> 0.022727273
A7: 331 | B7: 0.24 | C7: 0.64 | D7: 0.24 | E7: 0.03
A8: =A6+50 -> 350 | B8: =1 - COUNTIF('Результаты опроса'!L:L, "<=" & A8)/88 -> 0.23863636 | C8: =1 - COUNTIF('Результаты опроса'!M:M, "<=" & A8)/88 -> 0.60227273 | D8: =1 - COUNTIF('Результаты опроса'!N:N, ">=" & A8)/88 -> 0.36363636 | E8: =1 - COUNTIF('Результаты опроса'!O:O, ">=" & A8)/88 -> 0.045454545
A9: =A8+50 -> 400 | B9: =1 - COUNTIF('Результаты опроса'!L:L, "<=" & A9)/88 -> 0.23863636 | C9: =1 - COUNTIF('Результаты опроса'!M:M, "<=" & A9)/88 -> 0.45454545 | D9: =1 - COUNTIF('Результаты опроса'!N:N, ">=" & A9)/88 -> 0.38636364 | E9: =1 - COUNTIF('Результаты опроса'!O:O, ">=" & A9)/88 -> 0.045454545
A10: 443 | B10: 0.23 | C10: 0.41 | D10: 0.41 | E10: 0.07
A11: =A9+50 -> 450 | B11: =1 - COUNTIF('Результаты опроса'!L:L, "<=" & A11)/88 -> 0.22727273 | C11: =1 - COUNTIF('Результаты опроса'!M:M, "<=" & A11)/88 -> 0.40909091 | D11: =1 - COUNTIF('Результаты опроса'!N:N, ">=" & A11)/88 -> 0.42045455 | E11: =1 - COUNTIF('Результаты опроса'!O:O, ">=" & A11)/88 -> 0.079545455
A12: 483 | B12: 0.08 | C12: 0.31 | D12: 0.43 | E12: 0.08
A13: =A11+50 -> 500 | B13: =1 - COUNTIF('Результаты опроса'!L:L, "<=" & A13)/88 -> 0 | C13: =1 - COUNTIF('Результаты опроса'!M:M, "<=" & A13)/88 -> 0.26136364 | D13: =1 - COUNTIF('Результаты опроса'!N:N, ">=" & A13)/88 -> 0.43181818 | E13: =1 - COUNTIF('Результаты опроса'!O:O, ">=" & A13)/88 -> 0.079545455
A14: =A13+50 -> 550 | B14: =1 - COUNTIF('Результаты опроса'!L:L, "<=" & A14)/88 -> 0 | C14: =1 - COUNTIF('Результаты опроса'!M:M, "<=" & A14)/88 -> 0.26136364 | D14: =1 - COUNTIF('Результаты опроса'!N:N, ">=" & A14)/88 -> 0.55681818 | E14: =1 - COUNTIF('Результаты опроса'!O:O, ">=" & A14)/88 -> 0.125
A15: =A14+50 -> 600 | B15: =1 - COUNTIF('Результаты опроса'!L:L, "<=" & A15)/88 -> 0 | C15: =1 - COUNTIF('Результаты опроса'!M:M, "<=" & A15)/88 -> 0.26136364 | D15: =1 - COUNTIF('Результаты опроса'!N:N, ">=" & A15)/88 -> 0.56818182 | E15: =1 - COUNTIF('Результаты опроса'!O:O, ">=" & A15)/88 -> 0.13636364
A16: =A15+50 -> 650 | B16: =1 - COUNTIF('Результаты опроса'!L:L, "<=" & A16)/88 -> 0 | C16: =1 - COUNTIF('Результаты опроса'!M:M, "<=" & A16)/88 -> 0.26136364 | D16: =1 - COUNTIF('Результаты опроса'!N:N, ">=" & A16)/88 -> 0.68181818 | E16: =1 - COUNTIF('Результаты опроса'!O:O, ">=" & A16)/88 -> 0.18181818
A17: =A16+50 -> 700 | B17: =1 - COUNTIF('Результаты опроса'!L:L, "<=" & A17)/88 -> 0 | C17: =1 - COUNTIF('Результаты опроса'!M:M, "<=" & A17)/88 -> 0.22727273 | D17: =1 - COUNTIF('Результаты опроса'!N:N, ">=" & A17)/88 -> 0.69318182 | E17: =1 - COUNTIF('Результаты опроса'!O:O, ">=" & A17)/88 -> 0.18181818
A18: 740 | B18: 0 | C18: 0.23 | D18: 0.71 | E18: 0.23
A19: =A17+50 -> 750 | B19: =1 - COUNTIF('Результаты опроса'!L:L, "<=" & A19)/88 -> 0 | C19: =1 - COUNTIF('Результаты опроса'!M:M, "<=" & A19)/88 -> 0.22727273 | D19: =1 - COUNTIF('Результаты опроса'!N:N, ">=" & A19)/88 -> 0.71590909 | E19: =1 - COUNTIF('Результаты опроса'!O:O, ">=" & A19)/88 -> 0.23863636
A20: =A19+50 -> 800 | B20: =1 - COUNTIF('Результаты опроса'!L:L, "<=" & A20)/88 -> 0 | C20: =1 - COUNTIF('Результаты опроса'!M:M, "<=" & A20)/88 -> 0.21590909 | D20: =1 - COUNTIF('Результаты опроса'!N:N, ">=" & A20)/88 -> 0.72727273 | E20: =1 - COUNTIF('Результаты опроса'!O:O, ">=" & A20)/88 -> 0.25
A21: =A20+50 -> 850 | B21: =1 - COUNTIF('Результаты опроса'!L:L, "<=" & A21)/88 -> 0 | C21: =1 - COUNTIF('Результаты опроса'!M:M, "<=" & A21)/88 -> 0.21590909 | D21: =1 - COUNTIF('Результаты опроса'!N:N, ">=" & A21)/88 -> 0.77272727 | E21: =1 - COUNTIF('Результаты опроса'!O:O, ">=" & A21)/88 -> 0.27272727
A22: =A21+50 -> 900 | B22: =1 - COUNTIF('Результаты опроса'!L:L, "<=" & A22)/88 -> 0 | C22: =1 - COUNTIF('Результаты опроса'!M:M, "<=" & A22)/88 -> 0.21590909 | D22: =1 - COUNTIF('Результаты опроса'!N:N, ">=" & A22)/88 -> 0.77272727 | E22: =1 - COUNTIF('Результаты опроса'!O:O, ">=" & A22)/88 -> 0.27272727
A23: =A22+50 -> 950 | B23: =1 - COUNTIF('Результаты опроса'!L:L, "<=" & A23)/88 -> 0 | C23: =1 - COUNTIF('Результаты опроса'!M:M, "<=" & A23)/88 -> 0.21590909 | D23: =1 - COUNTIF('Результаты опроса'!N:N, ">=" & A23)/88 -> 0.78409091 | E23: =1 - COUNTIF('Результаты опроса'!O:O, ">=" & A23)/88 -> 0.27272727
A24: =A23+50 -> 1000 | B24: =1 - COUNTIF('Результаты опроса'!L:L, "<=" & A24)/88 -> 0 | C24: =1 - COUNTIF('Результаты опроса'!M:M, "<=" & A24)/88 -> 0.011363636 | D24: =1 - COUNTIF('Результаты опроса'!N:N, ">=" & A24)/88 -> 0.79545455 | E24: =1 - COUNTIF('Результаты опроса'!O:O, ">=" & A24)/88 -> 0.27272727
